Traceback (most recent call last):
  File "/home/trade/anaconda3/lib/python3.8/site-packages/jupyter_cache/executors/utils.py", line 51, in single_nb_execution
    executenb(
  File "/home/trade/anaconda3/lib/python3.8/site-packages/nbclient/client.py", line 1082, in execute
    return NotebookClient(nb=nb, resources=resources, km=km, **kwargs).execute()
  File "/home/trade/anaconda3/lib/python3.8/site-packages/nbclient/util.py", line 74, in wrapped
    return just_run(coro(*args, **kwargs))
  File "/home/trade/anaconda3/lib/python3.8/site-packages/nbclient/util.py", line 53, in just_run
    return loop.run_until_complete(coro)
  File "/home/trade/anaconda3/lib/python3.8/asyncio/base_events.py", line 616, in run_until_complete
    return future.result()
  File "/home/trade/anaconda3/lib/python3.8/site-packages/nbclient/client.py", line 535, in async_execute
    await self.async_execute_cell(
  File "/home/trade/anaconda3/lib/python3.8/site-packages/nbclient/client.py", line 827, in async_execute_cell
    self._check_raise_for_error(cell, exec_reply)
  File "/home/trade/anaconda3/lib/python3.8/site-packages/nbclient/client.py", line 735, in _check_raise_for_error
    raise CellExecutionError.from_cell_and_msg(cell, exec_reply['content'])
nbclient.exceptions.CellExecutionError: An error occurred while executing the following cell:
------------------
from sklearn.datasets import load_boston
boston = load_boston()
dfX = pd.DataFrame(boston.data, columns=boston.feature_names)
dfy = pd.DataFrame(boston.target, columns=["MEDV"])
df = pd.concat([dfX, dfy], axis=1)
------------------

[0;31m---------------------------------------------------------------------------[0m
[0;31mNameError[0m                                 Traceback (most recent call last)
[0;32m<ipython-input-1-a71b6f8fe2f5>[0m in [0;36m<module>[0;34m[0m
[1;32m      1[0m [0;32mfrom[0m [0msklearn[0m[0;34m.[0m[0mdatasets[0m [0;32mimport[0m [0mload_boston[0m[0;34m[0m[0;34m[0m[0m
[1;32m      2[0m [0mboston[0m [0;34m=[0m [0mload_boston[0m[0;34m([0m[0;34m)[0m[0;34m[0m[0;34m[0m[0m
[0;32m----> 3[0;31m [0mdfX[0m [0;34m=[0m [0mpd[0m[0;34m.[0m[0mDataFrame[0m[0;34m([0m[0mboston[0m[0;34m.[0m[0mdata[0m[0;34m,[0m [0mcolumns[0m[0;34m=[0m[0mboston[0m[0;34m.[0m[0mfeature_names[0m[0;34m)[0m[0;34m[0m[0;34m[0m[0m
[0m[1;32m      4[0m [0mdfy[0m [0;34m=[0m [0mpd[0m[0;34m.[0m[0mDataFrame[0m[0;34m([0m[0mboston[0m[0;34m.[0m[0mtarget[0m[0;34m,[0m [0mcolumns[0m[0;34m=[0m[0;34m[[0m[0;34m"MEDV"[0m[0;34m][0m[0;34m)[0m[0;34m[0m[0;34m[0m[0m
[1;32m      5[0m [0mdf[0m [0;34m=[0m [0mpd[0m[0;34m.[0m[0mconcat[0m[0;34m([0m[0;34m[[0m[0mdfX[0m[0;34m,[0m [0mdfy[0m[0;34m][0m[0;34m,[0m [0maxis[0m[0;34m=[0m[0;36m1[0m[0;34m)[0m[0;34m[0m[0;34m[0m[0m

[0;31mNameError[0m: name 'pd' is not defined
NameError: name 'pd' is not defined

